Workbook

Sheet tips
A1: sex | B1: smoker | C1: day | D1: time | E1: Tip | F1: size | G1: total_bill | H1: Sex2 | I1: Smoker3 | J1: Day4 | K1: Time2
A2: Female | B2: No | C2: Sun | D2: Dinner | E2: 1.01 | F2: 2 | G2: 16.99 | H2: =IF($A2 = "Male",1,2) -> 2 | I2: =IF($B2 = "Yes",1,2) -> 2 | J2: =IF(C2="Sun", 1, IF(C2="Sat", 2, IF(C2="Thur", 3, IF(C2="Fri", 4, "")))) -> 1 | K2: =IF($D2 = "Dinner",1,2) -> 1
A3: Male | B3: No | C3: Sun | D3: Dinner | E3: 1.66 | F3: 3 | G3: 10.34 | H3: =IF($A3 = "Male",1,2) -> 1 | I3: =IF($B3 = "Yes",1,2) -> 2 | J3: =IF(C3="Sun", 1, IF(C3="Sat", 2, IF(C3="Thur", 3, IF(C3="Fri", 4, "")))) -> 1 | K3: =IF($D3 = "Dinner",1,2) -> 1 | M3: sex | N3: Gender of the customer | R3: Tip | S3: size | T3: total_bill | U3: Sex2 | V3: Smoker3 | W3: Day4 | X3: Time2
A4: Male | B4: No | C4: Sun | D4: Dinner | E4: 3.5 | F4: 3 | G4: 21.01 | H4: =IF($A4 = "Male",1,2) -> 1 | I4: =IF($B4 = "Yes",1,2) -> 2 | J4: =IF(C4="Sun", 1, IF(C4="Sat", 2, IF(C4="Thur", 3, IF(C4="Fri", 4, "")))) -> 1 | K4: =IF($D4 = "Dinner",1,2) -> 1 | M4: smoker | N4: Indicates if the customer is a smoker or not | Q4: Tip | R4: 1
A5: Male | B5: No | C5: Sun | D5: Dinner | E5: 3.31 | F5: 2 | G5: 23.68 | H5: =IF($A5 = "Male",1,2) -> 1 | I5: =IF($B5 = "Yes",1,2) -> 2 | J5: =IF(C5="Sun", 1, IF(C5="Sat", 2, IF(C5="Thur", 3, IF(C5="Fri", 4, "")))) -> 1 | K5: =IF($D5 = "Dinner",1,2) -> 1 | M5: day | N5: Day of the restaurant visit | Q5: size | R5: 0.48929878 | S5: 1
A6: Female | B6: No | C6: Sun | D6: Dinner | E6: 3.61 | F6: 4 | G6: 24.59 | H6: =IF($A6 = "Male",1,2) -> 2 | I6: =IF($B6 = "Yes",1,2) -> 2 | J6: =IF(C6="Sun", 1, IF(C6="Sat", 2, IF(C6="Thur", 3, IF(C6="Fri", 4, "")))) -> 1 | K6: =IF($D6 = "Dinner",1,2) -> 1 | M6: time | N6: Indicates whether the tip was for lunch or dinner | Q6: total_bill | R6: 0.67573411 | S6: 0.59831513 | T6: 1
A7: Male | B7: No | C7: Sun | D7: Dinner | E7: 4.71 | F7: 4 | G7: 25.29 | H7: =IF($A7 = "Male",1,2) -> 1 | I7: =IF($B7 = "Yes",1,2) -> 2 | J7: =IF(C7="Sun", 1, IF(C7="Sat", 2, IF(C7="Thur", 3, IF(C7="Fri", 4, "")))) -> 1 | K7: =IF($D7 = "Dinner",1,2) -> 1 | M7: size | N7: Number of members dining | Q7: Sex2 | R7: -0.088862061 | S7: -0.086194815 | T7: -0.14487734 | U7: 1
A8: Male | B8: No | C8: Sun | D8: Dinner | E8: 2 | F8: 2 | G8: 8.77 | H8: =IF($A8 = "Male",1,2) -> 1 | I8: =IF($B8 = "Yes",1,2) -> 2 | J8: =IF(C8="Sun", 1, IF(C8="Sat", 2, IF(C8="Thur", 3, IF(C8="Fri", 4, "")))) -> 1 | K8: =IF($D8 = "Dinner",1,2) -> 1 | M8: total bill | N8: Bill amount in USD | Q8: Smoker3 | R8: -0.0059285395 | S8: 0.13317825 | T8: -0.085721257 | U8: 0.0028159517 | V8: 1
A9: Male | B9: No | C9: Sun | D9: Dinner | E9: 3.12 | F9: 4 | G9: 26.88 | H9: =IF($A9 = "Male",1,2) -> 1 | I9: =IF($B9 = "Yes",1,2) -> 2 | J9: =IF(C9="Sun", 1, IF(C9="Sat", 2, IF(C9="Thur", 3, IF(C9="Fri", 4, "")))) -> 1 | K9: =IF($D9 = "Dinner",1,2) -> 1 | M9: tip | N9: Tip amount in USD | Q9: Day4 | R9: -0.13894712 | S9: -0.21175021 | T9: -0.17531197 | U9: 0.21537409 | V9: -0.17081845 | W9: 1
A10: Male | B10: No | C10: Sun | D10: Dinner | E10: 1.96 | F10: 2 | G10: 15.04 | H10: =IF($A10 = "Male",1,2) -> 1 | I10: =IF($B10 = "Yes",1,2) -> 2 | J10: =IF(C10="Sun", 1, IF(C10="Sat", 2, IF(C10="Thur", 3, IF(C10="Fri", 4, "")))) -> 1 | K10: =IF($D10 = "Dinner",1,2) -> 1 | Q10: Time2 | R10: -0.12162906 | S10: -0.10341091 | T10: -0.18311761 | U10: 0.2052313 | V10: 0.054921104 | W10: 0.67047036 | X10: 1
A11: Male | B11: No | C11: Sun | D11: Dinner | E11: 3.23 | F11: 2 | G11: 14.78 | H11: =IF($A11 = "Male",1,2) -> 1 | I11: =IF($B11 = "Yes",1,2) -> 2 | J11: =IF(C11="Sun", 1, IF(C11="Sat", 2, IF(C11="Thur", 3, IF(C11="Fri", 4, "")))) -> 1 | K11: =IF($D11 = "Dinner",1,2) -> 1
A12: Male | B12: No | C12: Sun | D12: Dinner | E12: 1.71 | F12: 2 | G12: 10.27 | H12: =IF($A12 = "Male",1,2) -> 1 | I12: =IF($B12 = "Yes",1,2) -> 2 | J12: =IF(C12="Sun", 1, IF(C12="Sat", 2, IF(C12="Thur", 3, IF(C12="Fri", 4, "")))) -> 1 | K12: =IF($D12 = "Dinner",1,2) -> 1 | M12: Sex
A13: Female | B13: No | C13: Sun | D13: Dinner | E13: 5 | F13: 4 | G13: 35.26 | H13: =IF($A13 = "Male",1,2) -> 2 | I13: =IF($B13 = "Yes",1,2) -> 2 | J13: =IF(C13="Sun", 1, IF(C13="Sat", 2, IF(C13="Thur", 3, IF(C13="Fri", 4, "")))) -> 1 | K13: =IF($D13 = "Dinner",1,2) -> 1 | M13: Male | N13: 1 | Q13: SUMMARY OUTPUT
A14: Male | B14: No | C14: Sun | D14: Dinner | E14: 1.57 | F14: 2 | G14: 15.42 | H14: =IF($A14 = "Male",1,2) -> 1 | I14: =IF($B14 = "Yes",1,2) -> 2 | J14: =IF(C14="Sun", 1, IF(C14="Sat", 2, IF(C14="Thur", 3, IF(C14="Fri", 4, "")))) -> 1 | K14: =IF($D14 = "Dinner",1,2) -> 1 | M14: Female | N14: 2
A15: Male | B15: No | C15: Sun | D15: Dinner | E15: 3 | F15: 4 | G15: 18.43 | H15: =IF($A15 = "Male",1,2) -> 1 | I15: =IF($B15 = "Yes",1,2) -> 2 | J15: =IF(C15="Sun", 1, IF(C15="Sat", 2, IF(C15="Thur", 3, IF(C15="Fri", 4, "")))) -> 1 | K15: =IF($D15 = "Dinner",1,2) -> 1 | Q15: Regression Statistics
A16: Female | B16: No | C16: Sun | D16: Dinner | E16: 3.02 | F16: 2 | G16: 14.83 | H16: =IF($A16 = "Male",1,2) -> 2 | I16: =IF($B16 = "Yes",1,2) -> 2 | J16: =IF(C16="Sun", 1, IF(C16="Sat", 2, IF(C16="Thur", 3, IF(C16="Fri", 4, "")))) -> 1 | K16: =IF($D16 = "Dinner",1,2) -> 1 | M16: Smoker | Q16: Multiple R | R16: 0.68467665
A17: Male | B17: No | C17: Sun | D17: Dinner | E17: 3.92 | F17: 2 | G17: 21.58 | H17: =IF($A17 = "Male",1,2) -> 1 | I17: =IF($B17 = "Yes",1,2) -> 2 | J17: =IF(C17="Sun", 1, IF(C17="Sat", 2, IF(C17="Thur", 3, IF(C17="Fri", 4, "")))) -> 1 | K17: =IF($D17 = "Dinner",1,2) -> 1 | M17: Yes | N17: 1 | Q17: R Square | R17: 0.46878212
A18: Female | B18: No | C18: Sun | D18: Dinner | E18: 1.67 | F18: 3 | G18: 10.33 | H18: =IF($A18 = "Male",1,2) -> 2 | I18: =IF($B18 = "Yes",1,2) -> 2 | J18: =IF(C18="Sun", 1, IF(C18="Sat", 2, IF(C18="Thur", 3, IF(C18="Fri", 4, "")))) -> 1 | K18: =IF($D18 = "Dinner",1,2) -> 1 | M18: No | N18: 2 | Q18: Adjusted R Square | R18: 0.45533357
A19: Male | B19: No | C19: Sun | D19: Dinner | E19: 3.71 | F19: 3 | G19: 16.29 | H19: =IF($A19 = "Male",1,2) -> 1 | I19: =IF($B19 = "Yes",1,2) -> 2 | J19: =IF(C19="Sun", 1, IF(C19="Sat", 2, IF(C19="Thur", 3, IF(C19="Fri", 4, "")))) -> 1 | K19: =IF($D19 = "Dinner",1,2) -> 1 | Q19: Standard Error | R19: 1.021146
A20: Female | B20: No | C20: Sun | D20: Dinner | E20: 3.5 | F20: 3 | G20: 16.97 | H20: =IF($A20 = "Male",1,2) -> 2 | I20: =IF($B20 = "Yes",1,2) -> 2 | J20: =IF(C20="Sun", 1, IF(C20="Sat", 2, IF(C20="Thur", 3, IF(C20="Fri", 4, "")))) -> 1 | K20: =IF($D20 = "Dinner",1,2) -> 1 | M20: Day | Q20: Observations | R20: 244
A21: Male | B21: No | C21: Sat | D21: Dinner | E21: 3.35 | F21: 3 | G21: 20.65 | H21: =IF($A21 = "Male",1,2) -> 1 | I21: =IF($B21 = "Yes",1,2) -> 2 | J21: =IF(C21="Sun", 1, IF(C21="Sat", 2, IF(C21="Thur", 3, IF(C21="Fri", 4, "")))) -> 2 | K21: =IF($D21 = "Dinner",1,2) -> 1 | M21: Sun | N21: 1
A22: Male | B22: No | C22: Sat | D22: Dinner | E22: 4.08 | F22: 2 | G22: 17.92 | H22: =IF($A22 = "Male",1,2) -> 1 | I22: =IF($B22 = "Yes",1,2) -> 2 | J22: =IF(C22="Sun", 1, IF(C22="Sat", 2, IF(C22="Thur", 3, IF(C22="Fri", 4, "")))) -> 2 | K22: =IF($D22 = "Dinner",1,2) -> 1 | M22: Sat | N22: 2 | Q22: ANOVA
A23: Female | B23: No | C23: Sat | D23: Dinner | E23: 2.75 | F23: 2 | G23: 20.29 | H23: =IF($A23 = "Male",1,2) -> 2 | I23: =IF($B23 = "Yes",1,2) -> 2 | J23: =IF(C23="Sun", 1, IF(C23="Sat", 2, IF(C23="Thur", 3, IF(C23="Fri", 4, "")))) -> 2 | K23: =IF($D23 = "Dinner",1,2) -> 1 | M23: Thur | N23: 3 | R23: df | S23: SS | T23: MS | U23: F | V23: Significance F
A24: Female | B24: No | C24: Sat | D24: Dinner | E24: 2.23 | F24: 2 | G24: 15.77 | H24: =IF($A24 = "Male",1,2) -> 2 | I24: =IF($B24 = "Yes",1,2) -> 2 | J24: =IF(C24="Sun", 1, IF(C24="Sat", 2, IF(C24="Thur", 3, IF(C24="Fri", 4, "")))) -> 2 | K24: =IF($D24 = "Dinner",1,2) -> 1 | M24: Fri | N24: 4 | Q24: Regression | R24: 6 | S24: 218.08329 | T24: 36.347215 | U24: 34.857437 | V24: 4.4907153e-30
A25: Male | B25: No | C25: Sat | D25: Dinner | E25: 7.58 | F25: 4 | G25: 39.42 | H25: =IF($A25 = "Male",1,2) -> 1 | I25: =IF($B25 = "Yes",1,2) -> 2 | J25: =IF(C25="Sun", 1, IF(C25="Sat", 2, IF(C25="Thur", 3, IF(C25="Fri", 4, "")))) -> 2 | K25: =IF($D25 = "Dinner",1,2) -> 1 | Q25: Residual | R25: 237 | S25: 247.12919 | T25: 1.0427392
A26: Male | B26: No | C26: Sat | D26: Dinner | E26: 3.18 | F26: 2 | G26: 19.82 | H26: =IF($A26 = "Male",1,2) -> 1 | I26: =IF($B26 = "Yes",1,2) -> 2 | J26: =IF(C26="Sun", 1, IF(C26="Sat", 2, IF(C26="Thur", 3, IF(C26="Fri", 4, "")))) -> 2 | K26: =IF($D26 = "Dinner",1,2) -> 1 | M26: Time | Q26: Total | R26: 243 | S26: 465.21248
A27: Male | B27: No | C27: Sat | D27: Dinner | E27: 2.34 | F27: 4 | G27: 17.81 | H27: =IF($A27 = "Male",1,2) -> 1 | I27: =IF($B27 = "Yes",1,2) -> 2 | J27: =IF(C27="Sun", 1, IF(C27="Sat", 2, IF(C27="Thur", 3, IF(C27="Fri", 4, "")))) -> 2 | K27: =IF($D27 = "Dinner",1,2) -> 1 | M27: Dinner | N27: 1
A28: Male | B28: No | C28: Sat | D28: Dinner | E28: 2 | F28: 2 | G28: 13.37 | H28: =IF($A28 = "Male",1,2) -> 1 | I28: =IF($B28 = "Yes",1,2) -> 2 | J28: =IF(C28="Sun", 1, IF(C28="Sat", 2, IF(C28="Thur", 3, IF(C28="Fri", 4, "")))) -> 2 | K28: =IF($D28 = "Dinner",1,2) -> 1 | M28: Lunch | N28: 2 | R28: Coefficients | S28: Standard Error | T28: t Stat | U28: P-value | V28: Lower 95% | W28: Upper 95% | X28: Lower 95.0% | Y28: Upper 95.0%
A29: Male | B29: No | C29: Sat | D29: Dinner | E29: 2 | F29: 2 | G29: 12.69 | H29: =IF($A29 = "Male",1,2) -> 1 | I29: =IF($B29 = "Yes",1,2) -> 2 | J29: =IF(C29="Sun", 1, IF(C29="Sat", 2, IF(C29="Thur", 3, IF(C29="Fri", 4, "")))) -> 2 | K29: =IF($D29 = "Dinner",1,2) -> 1 | Q29: Intercept | R29: 0.51428098 | S29: 0.40895875 | T29: 1.2575376 | U29: 0.20979676 | V29: -0.29137757 | W29: 1.3199395 | X29: -0.29137757 | Y29: 1.3199395
A30: Male | B30: No | C30: Sat | D30: Dinner | E30: 4.3 | F30: 2 | G30: 21.7 | H30: =IF($A30 = "Male",1,2) -> 1 | I30: =IF($B30 = "Yes",1,2) -> 2 | J30: =IF(C30="Sun", 1, IF(C30="Sat", 2, IF(C30="Thur", 3, IF(C30="Fri", 4, "")))) -> 2 | K30: =IF($D30 = "Dinner",1,2) -> 1 | Q30: size | R30: 0.17936677 | S30: 0.089111038 | T30: 2.0128456 | U30: 0.04526196 | V30: 0.0038158802 | W30: 0.35491765 | X30: 0.0038158802 | Y30: 0.35491765
A31: Female | B31: No | C31: Sat | D31: Dinner | E31: 3 | F31: 2 | G31: 19.65 | H31: =IF($A31 = "Male",1,2) -> 2 | I31: =IF($B31 = "Yes",1,2) -> 2 | J31: =IF(C31="Sun", 1, IF(C31="Sat", 2, IF(C31="Thur", 3, IF(C31="Fri", 4, "")))) -> 2 | K31: =IF($D31 = "Dinner",1,2) -> 1 | Q31: total_bill | R31: 0.094075953 | S31: 0.0095243995 | T31: 9.8773631 | U31: 1.7161335e-19 | V31: 0.075312657 | W31: 0.11283925 | X31: 0.075312657 | Y31: 0.11283925
A32: Male | B32: No | C32: Sat | D32: Dinner | E32: 1.45 | F32: 2 | G32: 9.55 | H32: =IF($A32 = "Male",1,2) -> 1 | I32: =IF($B32 = "Yes",1,2) -> 2 | J32: =IF(C32="Sun", 1, IF(C32="Sat", 2, IF(C32="Thur", 3, IF(C32="Fri", 4, "")))) -> 2 | K32: =IF($D32 = "Dinner",1,2) -> 1 | Q32: Sex2 | R32: 0.029216083 | S32: 0.14106002 | T32: 0.2071181 | U32: 0.83609547 | V32: -0.24867554 | W32: 0.30710771 | X32: -0.24867554 | Y32: 0.30710771
A33: Male | B33: No | C33: Sat | D33: Dinner | E33: 2.5 | F33: 4 | G33: 18.35 | H33: =IF($A33 = "Male",1,2) -> 1 | I33: =IF($B33 = "Yes",1,2) -> 2 | J33: =IF(C33="Sun", 1, IF(C33="Sat", 2, IF(C33="Thur", 3, IF(C33="Fri", 4, "")))) -> 2 | K33: =IF($D33 = "Dinner",1,2) -> 1 | Q33: Smoker3 | R33: 0.081040508 | S33: 0.14374225 | T33: 0.56379045 | U33: 0.57342983 | V33: -0.20213517 | W33: 0.36421619 | X33: -0.20213517 | Y33: 0.36421619
A34: Female | B34: No | C34: Sat | D34: Dinner | E34: 3 | F34: 2 | G34: 15.06 | H34: =IF($A34 = "Male",1,2) -> 2 | I34: =IF($B34 = "Yes",1,2) -> 2 | J34: =IF(C34="Sun", 1, IF(C34="Sat", 2, IF(C34="Thur", 3, IF(C34="Fri", 4, "")))) -> 2 | K34: =IF($D34 = "Dinner",1,2) -> 1 | Q34: Day4 | R34: -0.007833821 | S34: 0.10038112 | T34: -0.07804078 | U34: 0.93786146 | V34: -0.20558704 | W34: 0.1899194 | X34: -0.20558704 | Y34: 0.1899194
A35: Female | B35: No | C35: Sat | D35: Dinner | E35: 2.45 | F35: 4 | G35: 20.69 | H35: =IF($A35 = "Male",1,2) -> 2 | I35: =IF($B35 = "Yes",1,2) -> 2 | J35: =IF(C35="Sun", 1, IF(C35="Sat", 2, IF(C35="Thur", 3, IF(C35="Fri", 4, "")))) -> 2 | K35: =IF($D35 = "Dinner",1,2) -> 1 | Q35: Time2 | R35: 0.0057205401 | S35: 0.20369712 | T35: 0.028083559 | U35: 0.97761914 | V35: -0.39556768 | W35: 0.40700876 | X35: -0.39556768 | Y35: 0.40700876
A36: Male | B36: No | C36: Sat | D36: Dinner | E36: 3.27 | F36: 2 | G36: 17.78 | H36: =IF($A36 = "Male",1,2) -> 1 | I36: =IF($B36 = "Yes",1,2) -> 2 | J36: =IF(C36="Sun", 1, IF(C36="Sat", 2, IF(C36="Thur", 3, IF(C36="Fri", 4, "")))) -> 2 | K36: =IF($D36 = "Dinner",1,2) -> 1
A37: Male | B37: No | C37: Sat | D37: Dinner | E37: 3.6 | F37: 3 | G37: 24.06 | H37: =IF($A37 = "Male",1,2) -> 1 | I37: =IF($B37 = "Yes",1,2) -> 2 | J37: =IF(C37="Sun", 1, IF(C37="Sat", 2, IF(C37="Thur", 3, IF(C37="Fri", 4, "")))) -> 2 | K37: =IF($D37 = "Dinner",1,2) -> 1
A38: Male | B38: No | C38: Sat | D38: Dinner | E38: 2 | F38: 3 | G38: 16.31 | H38: =IF($A38 = "Male",1,2) -> 1 | I38: =IF($B38 = "Yes",1,2) -> 2 | J38: =IF(C38="Sun", 1, IF(C38="Sat", 2, IF(C38="Thur", 3, IF(C38="Fri", 4, "")))) -> 2 | K38: =IF($D38 = "Dinner",1,2) -> 1
A39: Female | B39: No | C39: Sat | D39: Dinner | E39: 3.07 | F39: 3 | G39: 16.93 | H39: =IF($A39 = "Male",1,2) -> 2 | I39: =IF($B39 = "Yes",1,2) -> 2 | J39: =IF(C39="Sun", 1, IF(C39="Sat", 2, IF(C39="Thur", 3, IF(C39="Fri", 4, "")))) -> 2 | K39: =IF($D39 = "Dinner",1,2) -> 1
A40: Male | B40: No | C40: Sat | D40: Dinner | E40: 2.31 | F40: 3 | G40: 18.69 | H40: =IF($A40 = "Male",1,2) -> 1 | I40: =IF($B40 = "Yes",1,2) -> 2 | J40: =IF(C40="Sun", 1, IF(C40="Sat", 2, IF(C40="Thur", 3, IF(C40="Fri", 4, "")))) -> 2 | K40: =IF($D40 = "Dinner",1,2) -> 1
...

Sheet Working
E1: Value in US$ | T1: Sex | U1: Smoker | V1: Day | W1: Time | X1: Size | Y1: Total Bill | Z1: Tip | AA1: Predicted Tip | AF1: sex | AG1: smoker | AH1: day | AI1: time | AJ1: size | AK1: total_bill | AL1: Tip | AM1: Predicted Tip
L2: Tip | M2: size | N2: total_bill | O2: Sex2 | P2: Smoker3 | Q2: Day4 | R2: Dinner | T2: 2 | U2: 2 | V2: 1 | W2: 1 | X2: 2 | Y2: 16.99 | Z2: 1.01 | AA2: =$L$27+ $T2*($L$30) - $U2*($L$31) + $V2*($L$32) - $W2*($L$33) + $X2*($L$28) + $Y2*($L$29) -> 2.3541617 | AB2: 1.01 | AF2: Female | AG2: No | AH2: Sun | AI2: Dinner | AJ2: 2 | AK2: 16.99 | AL2: 1.01 | AM2: =$L$27+ $T2*($L$30) - $U2*($L$31) + $V2*($L$32) - $W2*($L$33) + $X2*($L$28) + $Y2*($L$29) -> 2.3541617
A3: Row Labels | B3: Sum of tip | F3: Row Labels | G3: Sum of tip | K3: Tip | L3: 1 | T3: 1 | U3: 2 | V3: 1 | W3: 1 | X3: 3 | Y3: 10.34 | Z3: 1.66 | AA3: =$L$27+ $T3*($L$30) - $U3*($L$31) + $V3*($L$32) - $W3*($L$33) + $X3*($L$28) + $Y3*($L$29) -> 1.8787073 | AB3: 1.66 | AF3: Male | AG3: No | AH3: Sun | AI3: Dinner | AJ3: 3 | AK3: 10.34 | AL3: 1.66 | AM3: =$L$27+ $T3*($L$30) - $U3*($L$31) + $V3*($L$32) - $W3*($L$33) + $X3*($L$28) + $Y3*($L$29) -> 1.8787073
A4: Female | B4: 246.51 | F4: Female | G4: 246.51 | K4: size | L4: 0.48929878 | M4: 1 | T4: 1 | U4: 2 | V4: 1 | W4: 1 | X4: 3 | Y4: 21.01 | Z4: 3.5 | AA4: =$L$27+ $T4*($L$30) - $U4*($L$31) + $V4*($L$32) - $W4*($L$33) + $X4*($L$28) + $Y4*($L$29) -> 2.8824978 | AB4: 3.5 | AF4: Male | AG4: No | AH4: Sun | AI4: Dinner | AJ4: 3 | AK4: 21.01 | AL4: 3.5 | AM4: =$L$27+ $T4*($L$30) - $U4*($L$31) + $V4*($L$32) - $W4*($L$33) + $X4*($L$28) + $Y4*($L$29) -> 2.8824978
A5: Male | B5: 485.07 | F5: Dinner | G5: 156.11 | K5: total_bill | L5: 0.67573411 | M5: 0.59831513 | N5: 1 | T5: 1 | U5: 2 | V5: 1 | W5: 1 | X5: 2 | Y5: 23.68 | Z5: 3.31 | AA5: =$L$27+ $T5*($L$30) - $U5*($L$31) + $V5*($L$32) - $W5*($L$33) + $X5*($L$28) + $Y5*($L$29) -> 2.9543138 | AB5: 3.31 | AF5: Male | AG5: No | AH5: Sun | AI5: Dinner | AJ5: 2 | AK5: 23.68 | AL5: 3.31 | AM5: =$L$27+ $T5*($L$30) - $U5*($L$31) + $V5*($L$32) - $W5*($L$33) + $X5*($L$28) + $Y5*($L$29) -> 2.9543138
A6: Grand Total | B6: 731.58 | F6: Lunch | G6: 90.4 | K6: Sex2 | L6: -0.088862061 | M6: -0.086194815 | N6: -0.14487734 | O6: 1 | T6: 2 | U6: 2 | V6: 1 | W6: 1 | X6: 4 | Y6: 24.59 | Z6: 3.61 | AA6: =$L$27+ $T6*($L$30) - $U6*($L$31) + $V6*($L$32) - $W6*($L$33) + $X6*($L$28) + $Y6*($L$29) -> 3.4278725 | AB6: 3.61 | AF6: Female | AG6: No | AH6: Sun | AI6: Dinner | AJ6: 4 | AK6: 24.59 | AL6: 3.61 | AM6: =$L$27+ $T6*($L$30) - $U6*($L$31) + $V6*($L$32) - $W6*($L$33) + $X6*($L$28) + $Y6*($L$29) -> 3.4278725 | AV6: 0
F7: Male | G7: 485.07 | K7: Smoker3 | L7: -0.0059285395 | M7: 0.13317825 | N7: -0.085721257 | O7: 0.0028159517 | P7: 1 | T7: 1 | U7: 2 | V7: 1 | W7: 1 | X7: 4 | Y7: 25.29 | Z7: 4.71 | AA7: =$L$27+ $T7*($L$30) - $U7*($L$31) + $V7*($L$32) - $W7*($L$33) + $X7*($L$28) + $Y7*($L$29) -> 3.4645096 | AB7: 4.71 | AF7: Male | AG7: No | AH7: Sun | AI7: Dinner | AJ7: 4 | AK7: 25.29 | AL7: 4.71 | AM7: =$L$27+ $T7*($L$30) - $U7*($L$31) + $V7*($L$32) - $W7*($L$33) + $X7*($L$28) + $Y7*($L$29) -> 3.4645096
F8: Dinner | G8: 389.96 | K8: Day4 | L8: -0.13894712 | M8: -0.21175021 | N8: -0.17531197 | O8: 0.21537409 | P8: -0.17081845 | Q8: 1 | T8: 1 | U8: 2 | V8: 1 | W8: 1 | X8: 2 | Y8: 8.77 | Z8: 2 | AA8: =$L$27+ $T8*($L$30) - $U8*($L$31) + $V8*($L$32) - $W8*($L$33) + $X8*($L$28) + $Y8*($L$29) -> 1.5516413 | AB8: 2 | AF8: Male | AG8: No | AH8: Sun | AI8: Dinner | AJ8: 2 | AK8: 8.77 | AL8: 2 | AM8: =$L$27+ $T8*($L$30) - $U8*($L$31) + $V8*($L$32) - $W8*($L$33) + $X8*($L$28) + $Y8*($L$29) -> 1.5516413
F9: Lunch | G9: 95.11 | K9: Dinner | L9: -0.12162906 | M9: -0.10341091 | N9: -0.18311761 | O9: 0.2052313 | P9: 0.054921104 | Q9: 0.67047036 | R9: 1 | T9: 1 | U9: 2 | V9: 1 | W9: 1 | X9: 4 | Y9: 26.88 | Z9: 3.12 | AA9: =$L$27+ $T9*($L$30) - $U9*($L$31) + $V9*($L$32) - $W9*($L$33) + $X9*($L$28) + $Y9*($L$29) -> 3.6140904 | AB9: 3.12 | AF9: Male | AG9: No | AH9: Sun | AI9: Dinner | AJ9: 4 | AK9: 26.88 | AL9: 3.12 | AM9: =$L$27+ $T9*($L$30) - $U9*($L$31) + $V9*($L$32) - $W9*($L$33) + $X9*($L$28) + $Y9*($L$29) -> 3.6140904
F10: Grand Total | G10: 731.58 | T10: 1 | U10: 2 | V10: 1 | W10: 1 | X10: 2 | Y10: 15.04 | Z10: 1.96 | AA10: =$L$27+ $T10*($L$30) - $U10*($L$31) + $V10*($L$32) - $W10*($L$33) + $X10*($L$28) + $Y10*($L$29) -> 2.1414975 | AB10: 1.96 | AF10: Male | AG10: No | AH10: Sun | AI10: Dinner | AJ10: 2 | AK10: 15.04 | AL10: 1.96 | AM10: =$L$27+ $T10*($L$30) - $U10*($L$31) + $V10*($L$32) - $W10*($L$33) + $X10*($L$28) + $Y10*($L$29) -> 2.1414975
K11: SUMMARY OUTPUT | T11: 1 | U11: 2 | V11: 1 | W11: 1 | X11: 2 | Y11: 14.78 | Z11: 3.23 | AA11: =$L$27+ $T11*($L$30) - $U11*($L$31) + $V11*($L$32) - $W11*($L$33) + $X11*($L$28) + $Y11*($L$29) -> 2.1170378 | AB11: 3.23 | AF11: Male | AG11: No | AH11: Sun | AI11: Dinner | AJ11: 2 | AK11: 14.78 | AL11: 3.23 | AM11: =$L$27+ $T11*($L$30) - $U11*($L$31) + $V11*($L$32) - $W11*($L$33) + $X11*($L$28) + $Y11*($L$29) -> 2.1170378
T12: 1 | U12: 2 | V12: 1 | W12: 1 | X12: 2 | Y12: 10.27 | Z12: 1.71 | AA12: =$L$27+ $T12*($L$30) - $U12*($L$31) + $V12*($L$32) - $W12*($L$33) + $X12*($L$28) + $Y12*($L$29) -> 1.6927553 | AB12: 1.71 | AF12: Male | AG12: No | AH12: Sun | AI12: Dinner | AJ12: 2 | AK12: 10.27 | AL12: 1.71 | AM12: =$L$27+ $T12*($L$30) - $U12*($L$31) + $V12*($L$32) - $W12*($L$33) + $X12*($L$28) + $Y12*($L$29) -> 1.6927553
K13: Regression Statistics | T13: 2 | U13: 2 | V13: 1 | W13: 1 | X13: 4 | Y13: 35.26 | Z13: 5 | AA13: =$L$27+ $T13*($L$30) - $U13*($L$31) + $V13*($L$32) - $W13*($L$33) + $X13*($L$28) + $Y13*($L$29) -> 4.4316629 | AB13: 5 | AF13: Female | AG13: No | AH13: Sun | AI13: Dinner | AJ13: 4 | AK13: 35.26 | AL13: 5 | AM13: =$L$27+ $T13*($L$30) - $U13*($L$31) + $V13*($L$32) - $W13*($L$33) + $X13*($L$28) + $Y13*($L$29) -> 4.4316629
K14: Multiple R | L14: 0.68467665 | T14: 1 | U14: 2 | V14: 1 | W14: 1 | X14: 2 | Y14: 15.42 | Z14: 1.57 | AA14: =$L$27+ $T14*($L$30) - $U14*($L$31) + $V14*($L$32) - $W14*($L$33) + $X14*($L$28) + $Y14*($L$29) -> 2.1772464 | AB14: 1.57 | AF14: Male | AG14: No | AH14: Sun | AI14: Dinner | AJ14: 2 | AK14: 15.42 | AL14: 1.57 | AM14: =$L$27+ $T14*($L$30) - $U14*($L$31) + $V14*($L$32) - $W14*($L$33) + $X14*($L$28) + $Y14*($L$29) -> 2.1772464
K15: R Square | L15: 0.46878212 | T15: 1 | U15: 2 | V15: 1 | W15: 1 | X15: 4 | Y15: 18.43 | Z15: 3 | AA15: =$L$27+ $T15*($L$30) - $U15*($L$31) + $V15*($L$32) - $W15*($L$33) + $X15*($L$28) + $Y15*($L$29) -> 2.8191486 | AB15: 3 | AF15: Male | AG15: No | AH15: Sun | AI15: Dinner | AJ15: 4 | AK15: 18.43 | AL15: 3 | AM15: =$L$27+ $T15*($L$30) - $U15*($L$31) + $V15*($L$32) - $W15*($L$33) + $X15*($L$28) + $Y15*($L$29) -> 2.8191486
K16: Adjusted R Square | L16: 0.45533357 | T16: 2 | U16: 2 | V16: 1 | W16: 1 | X16: 2 | Y16: 14.83 | Z16: 3.02 | AA16: =$L$27+ $T16*($L$30) - $U16*($L$31) + $V16*($L$32) - $W16*($L$33) + $X16*($L$28) + $Y16*($L$29) -> 2.1509577 | AB16: 3.02 | AF16: Female | AG16: No | AH16: Sun | AI16: Dinner | AJ16: 2 | AK16: 14.83 | AL16: 3.02 | AM16: =$L$27+ $T16*($L$30) - $U16*($L$31) + $V16*($L$32) - $W16*($L$33) + $X16*($L$28) + $Y16*($L$29) -> 2.1509577
K17: Standard Error | L17: 1.021146 | T17: 1 | U17: 2 | V17: 1 | W17: 1 | X17: 2 | Y17: 21.58 | Z17: 3.92 | AA17: =$L$27+ $T17*($L$30) - $U17*($L$31) + $V17*($L$32) - $W17*($L$33) + $X17*($L$28) + $Y17*($L$29) -> 2.7567543 | AB17: 3.92 | AF17: Male | AG17: No | AH17: Sun | AI17: Dinner | AJ17: 2 | AK17: 21.58 | AL17: 3.92 | AM17: =$L$27+ $T17*($L$30) - $U17*($L$31) + $V17*($L$32) - $W17*($L$33) + $X17*($L$28) + $Y17*($L$29) -> 2.7567543
K18: Observations | L18: 244 | T18: 2 | U18: 2 | V18: 1 | W18: 1 | X18: 3 | Y18: 10.33 | Z18: 1.67 | AA18: =$L$27+ $T18*($L$30) - $U18*($L$31) + $V18*($L$32) - $W18*($L$33) + $X18*($L$28) + $Y18*($L$29) -> 1.9069827 | AB18: 1.67 | AF18: Female | AG18: No | AH18: Sun | AI18: Dinner | AJ18: 3 | AK18: 10.33 | AL18: 1.67 | AM18: =$L$27+ $T18*($L$30) - $U18*($L$31) + $V18*($L$32) - $W18*($L$33) + $X18*($L$28) + $Y18*($L$29) -> 1.9069827
T19: 1 | U19: 2 | V19: 1 | W19: 1 | X19: 3 | Y19: 16.29 | Z19: 3.71 | AA19: =$L$27+ $T19*($L$30) - $U19*($L$31) + $V19*($L$32) - $W19*($L$33) + $X19*($L$28) + $Y19*($L$29) -> 2.4384593 | AB19: 3.71 | AF19: Male | AG19: No | AH19: Sun | AI19: Dinner | AJ19: 3 | AK19: 16.29 | AL19: 3.71 | AM19: =$L$27+ $T19*($L$30) - $U19*($L$31) + $V19*($L$32) - $W19*($L$33) + $X19*($L$28) + $Y19*($L$29) -> 2.4384593
K20: ANOVA | T20: 2 | U20: 2 | V20: 1 | W20: 1 | X20: 3 | Y20: 16.97 | Z20: 3.5 | AA20: =$L$27+ $T20*($L$30) - $U20*($L$31) + $V20*($L$32) - $W20*($L$33) + $X20*($L$28) + $Y20*($L$29) -> 2.531647 | AB20: 3.5 | AF20: Female | AG20: No | AH20: Sun | AI20: Dinner | AJ20: 3 | AK20: 16.97 | AL20: 3.5 | AM20: =$L$27+ $T20*($L$30) - $U20*($L$31) + $V20*($L$32) - $W20*($L$33) + $X20*($L$28) + $Y20*($L$29) -> 2.531647
L21: df | M21: SS | N21: MS | O21: F | P21: Significance F | T21: 1 | U21: 2 | V21: 2 | W21: 1 | X21: 3 | Y21: 20.65 | Z21: 3.35 | AA21: =$L$27+ $T21*($L$30) - $U21*($L$31) + $V21*($L$32) - $W21*($L$33) + $X21*($L$28) + $Y21*($L$29) -> 2.8407966 | AB21: 3.35 | AF21: Male | AG21: No | AH21: Sat | AI21: Dinner | AJ21: 3 | AK21: 20.65 | AL21: 3.35 | AM21: =$L$27+ $T21*($L$30) - $U21*($L$31) + $V21*($L$32) - $W21*($L$33) + $X21*($L$28) + $Y21*($L$29) -> 2.8407966
K22: Regression | L22: 6 | M22: 218.08329 | N22: 36.347215 | O22: 34.857437 | P22: 4.4907153e-30 | T22: 1 | U22: 2 | V22: 2 | W22: 1 | X22: 2 | Y22: 17.92 | Z22: 4.08 | AA22: =$L$27+ $T22*($L$30) - $U22*($L$31) + $V22*($L$32) - $W22*($L$33) + $X22*($L$28) + $Y22*($L$29) -> 2.4046025 | AB22: 4.08 | AF22: Male | AG22: No | AH22: Sat | AI22: Dinner | AJ22: 2 | AK22: 17.92 | AL22: 4.08 | AM22: =$L$27+ $T22*($L$30) - $U22*($L$31) + $V22*($L$32) - $W22*($L$33) + $X22*($L$28) + $Y22*($L$29) -> 2.4046025
K23: Residual | L23: 237 | M23: 247.12919 | N23: 1.0427392 | T23: 2 | U23: 2 | V23: 2 | W23: 1 | X23: 2 | Y23: 20.29 | Z23: 2.75 | AA23: =$L$27+ $T23*($L$30) - $U23*($L$31) + $V23*($L$32) - $W23*($L$33) + $X23*($L$28) + $Y23*($L$29) -> 2.6567786 | AB23: 2.75 | AF23: Female | AG23: No | AH23: Sat | AI23: Dinner | AJ23: 2 | AK23: 20.29 | AL23: 2.75 | AM23: =$L$27+ $T23*($L$30) - $U23*($L$31) + $V23*($L$32) - $W23*($L$33) + $X23*($L$28) + $Y23*($L$29) -> 2.6567786
K24: Total | L24: 243 | M24: 465.21248 | T24: 2 | U24: 2 | V24: 2 | W24: 1 | X24: 2 | Y24: 15.77 | Z24: 2.23 | AA24: =$L$27+ $T24*($L$30) - $U24*($L$31) + $V24*($L$32) - $W24*($L$33) + $X24*($L$28) + $Y24*($L$29) -> 2.2315553 | AB24: 2.23 | AF24: Female | AG24: No | AH24: Sat | AI24: Dinner | AJ24: 2 | AK24: 15.77 | AL24: 2.23 | AM24: =$L$27+ $T24*($L$30) - $U24*($L$31) + $V24*($L$32) - $W24*($L$33) + $X24*($L$28) + $Y24*($L$29) -> 2.2315553
T25: 1 | U25: 2 | V25: 2 | W25: 1 | X25: 4 | Y25: 39.42 | Z25: 7.58 | AA25: =$L$27+ $T25*($L$30) - $U25*($L$31) + $V25*($L$32) - $W25*($L$33) + $X25*($L$28) + $Y25*($L$29) -> 4.785969 | AB25: 7.58 | AF25: Male | AG25: No | AH25: Sat | AI25: Dinner | AJ25: 4 | AK25: 39.42 | AL25: 7.58 | AM25: =$L$27+ $T25*($L$30) - $U25*($L$31) + $V25*($L$32) - $W25*($L$33) + $X25*($L$28) + $Y25*($L$29) -> 4.785969
L26: Coefficients | M26: Standard Error | N26: t Stat | O26: P-value | P26: Lower 95% | Q26: Upper 95% | R26: Lower 95.0% | S26: Upper 95.0% | T26: 1 | U26: 2 | V26: 2 | W26: 1 | X26: 2 | Y26: 19.82 | Z26: 3.18 | AA26: =$L$27+ $T26*($L$30) - $U26*($L$31) + $V26*($L$32) - $W26*($L$33) + $X26*($L$28) + $Y26*($L$29) -> 2.5833468 | AB26: 3.18 | AF26: Male | AG26: No | AH26: Sat | AI26: Dinner | AJ26: 2 | AK26: 19.82 | AL26: 3.18 | AM26: =$L$27+ $T26*($L$30) - $U26*($L$31) + $V26*($L$32) - $W26*($L$33) + $X26*($L$28) + $Y26*($L$29) -> 2.5833468
K27: Intercept | L27: 0.51428098 | M27: 0.40895875 | N27: 1.2575376 | O27: 0.20979676 | P27: -0.29137757 | Q27: 1.3199395 | R27: -0.29137757 | S27: 1.3199395 | T27: 1 | U27: 2 | V27: 2 | W27: 1 | X27: 4 | Y27: 17.81 | Z27: 2.34 | AA27: =$L$27+ $T27*($L$30) - $U27*($L$31) + $V27*($L$32) - $W27*($L$33) + $X27*($L$28) + $Y27*($L$29) -> 2.7529876 | AB27: 2.34 | AF27: Male | AG27: No | AH27: Sat | AI27: Dinner | AJ27: 4 | AK27: 17.81 | AL27: 2.34 | AM27: =$L$27+ $T27*($L$30) - $U27*($L$31) + $V27*($L$32) - $W27*($L$33) + $X27*($L$28) + $Y27*($L$29) -> 2.7529876
K28: size | L28: 0.17936677 | M28: 0.089111038 | N28: 2.0128456 | O28: 0.04526196 | P28: 0.0038158802 | Q28: 0.35491765 | R28: 0.0038158802 | S28: 0.35491765 | T28: 1 | U28: 2 | V28: 2 | W28: 1 | X28: 2 | Y28: 13.37 | Z28: 2 | AA28: =$L$27+ $T28*($L$30) - $U28*($L$31) + $V28*($L$32) - $W28*($L$33) + $X28*($L$28) + $Y28*($L$29) -> 1.9765569 | AB28: 2 | AF28: Male | AG28: No | AH28: Sat | AI28: Dinner | AJ28: 2 | AK28: 13.37 | AL28: 2 | AM28: =$L$27+ $T28*($L$30) - $U28*($L$31) + $V28*($L$32) - $W28*($L$33) + $X28*($L$28) + $Y28*($L$29) -> 1.9765569
K29: total_bill | L29: 0.094075953 | M29: 0.0095243995 | N29: 9.8773631 | O29: 1.7161335e-19 | P29: 0.075312657 | Q29: 0.11283925 | R29: 0.075312657 | S29: 0.11283925 | T29: 1 | U29: 2 | V29: 2 | W29: 1 | X29: 2 | Y29: 12.69 | Z29: 2 | AA29: =$L$27+ $T29*($L$30) - $U29*($L$31) + $V29*($L$32) - $W29*($L$33) + $X29*($L$28) + $Y29*($L$29) -> 1.9125852 | AB29: 2 | AF29: Male | AG29: No | AH29: Sat | AI29: Dinner | AJ29: 2 | AK29: 12.69 | AL29: 2 | AM29: =$L$27+ $T29*($L$30) - $U29*($L$31) + $V29*($L$32) - $W29*($L$33) + $X29*($L$28) + $Y29*($L$29) -> 1.9125852
K30: Sex2 | L30: 0.029216083 | M30: 0.14106002 | N30: 0.2071181 | O30: 0.83609547 | P30: -0.24867554 | Q30: 0.30710771 | R30: -0.24867554 | S30: 0.30710771 | T30: 1 | U30: 2 | V30: 2 | W30: 1 | X30: 2 | Y30: 21.7 | Z30: 4.3 | AA30: =$L$27+ $T30*($L$30) - $U30*($L$31) + $V30*($L$32) - $W30*($L$33) + $X30*($L$28) + $Y30*($L$29) -> 2.7602096 | AB30: 4.3 | AF30: Male | AG30: No | AH30: Sat | AI30: Dinner | AJ30: 2 | AK30: 21.7 | AL30: 4.3 | AM30: =$L$27+ $T30*($L$30) - $U30*($L$31) + $V30*($L$32) - $W30*($L$33) + $X30*($L$28) + $Y30*($L$29) -> 2.7602096
K31: Smoker3 | L31: 0.081040508 | M31: 0.14374225 | N31: 0.56379045 | O31: 0.57342983 | P31: -0.20213517 | Q31: 0.36421619 | R31: -0.20213517 | S31: 0.36421619 | T31: 2 | U31: 2 | V31: 2 | W31: 1 | X31: 2 | Y31: 19.65 | Z31: 3 | AA31: =$L$27+ $T31*($L$30) - $U31*($L$31) + $V31*($L$32) - $W31*($L$33) + $X31*($L$28) + $Y31*($L$29) -> 2.59657 | AB31: 3 | AF31: Female | AG31: No | AH31: Sat | AI31: Dinner | AJ31: 2 | AK31: 19.65 | AL31: 3 | AM31: =$L$27+ $T31*($L$30) - $U31*($L$31) + $V31*($L$32) - $W31*($L$33) + $X31*($L$28) + $Y31*($L$29) -> 2.59657
K32: Day4 | L32: -0.007833821 | M32: 0.10038112 | N32: -0.07804078 | O32: 0.93786146 | P32: -0.20558704 | Q32: 0.1899194 | R32: -0.20558704 | S32: 0.1899194 | T32: 1 | U32: 2 | V32: 2 | W32: 1 | X32: 2 | Y32: 9.55 | Z32: 1.45 | AA32: =$L$27+ $T32*($L$30) - $U32*($L$31) + $V32*($L$32) - $W32*($L$33) + $X32*($L$28) + $Y32*($L$29) -> 1.6171867 | AB32: 1.45 | AF32: Male | AG32: No | AH32: Sat | AI32: Dinner | AJ32: 2 | AK32: 9.55 | AL32: 1.45 | AM32: =$L$27+ $T32*($L$30) - $U32*($L$31) + $V32*($L$32) - $W32*($L$33) + $X32*($L$28) + $Y32*($L$29) -> 1.6171867
K33: Dinner | L33: 0.0057205401 | M33: 0.20369712 | N33: 0.028083559 | O33: 0.97761914 | P33: -0.39556768 | Q33: 0.40700876 | R33: -0.39556768 | S33: 0.40700876 | T33: 1 | U33: 2 | V33: 2 | W33: 1 | X33: 4 | Y33: 18.35 | Z33: 2.5 | AA33: =$L$27+ $T33*($L$30) - $U33*($L$31) + $V33*($L$32) - $W33*($L$33) + $X33*($L$28) + $Y33*($L$29) -> 2.8037887 | AB33: 2.5 | AF33: Male | AG33: No | AH33: Sat | AI33: Dinner | AJ33: 4 | AK33: 18.35 | AL33: 2.5 | AM33: =$L$27+ $T33*($L$30) - $U33*($L$31) + $V33*($L$32) - $W33*($L$33) + $X33*($L$28) + $Y33*($L$29) -> 2.8037887
T34: 2 | U34: 2 | V34: 2 | W34: 1 | X34: 2 | Y34: 15.06 | Z34: 3 | AA34: =$L$27+ $T34*($L$30) - $U34*($L$31) + $V34*($L$32) - $W34*($L$33) + $X34*($L$28) + $Y34*($L$29) -> 2.1647613 | AB34: 3 | AF34: Female | AG34: No | AH34: Sat | AI34: Dinner | AJ34: 2 | AK34: 15.06 | AL34: 3 | AM34: =$L$27+ $T34*($L$30) - $U34*($L$31) + $V34*($L$32) - $W34*($L$33) + $X34*($L$28) + $Y34*($L$29) -> 2.1647613
T35: 2 | U35: 2 | V35: 2 | W35: 1 | X35: 4 | Y35: 20.69 | Z35: 2.45 | AA35: =$L$27+ $T35*($L$30) - $U35*($L$31) + $V35*($L$32) - $W35*($L$33) + $X35*($L$28) + $Y35*($L$29) -> 3.0531425 | AB35: 2.45 | AF35: Female | AG35: No | AH35: Sat | AI35: Dinner | AJ35: 4 | AK35: 20.69 | AL35: 2.45 | AM35: =$L$27+ $T35*($L$30) - $U35*($L$31) + $V35*($L$32) - $W35*($L$33) + $X35*($L$28) + $Y35*($L$29) -> 3.0531425
K36: Y = b0 + b1X1 + b2X2 + ... + bnXn | T36: 1 | U36: 2 | V36: 2 | W36: 1 | X36: 2 | Y36: 17.78 | Z36: 3.27 | AA36: =$L$27+ $T36*($L$30) - $U36*($L$31) + $V36*($L$32) - $W36*($L$33) + $X36*($L$28) + $Y36*($L$29) -> 2.3914318 | AB36: 3.27 | AF36: Male | AG36: No | AH36: Sat | AI36: Dinner | AJ36: 2 | AK36: 17.78 | AL36: 3.27 | AM36: =$L$27+ $T36*($L$30) - $U36*($L$31) + $V36*($L$32) - $W36*($L$33) + $X36*($L$28) + $Y36*($L$29) -> 2.3914318
K37: Where: | T37: 1 | U37: 2 | V37: 2 | W37: 1 | X37: 3 | Y37: 24.06 | Z37: 3.6 | AA37: =$L$27+ $T37*($L$30) - $U37*($L$31) + $V37*($L$32) - $W37*($L$33) + $X37*($L$28) + $Y37*($L$29) -> 3.1615956 | AB37: 3.6 | AF37: Male | AG37: No | AH37: Sat | AI37: Dinner | AJ37: 3 | AK37: 24.06 | AL37: 3.6 | AM37: =$L$27+ $T37*($L$30) - $U37*($L$31) + $V37*($L$32) - $W37*($L$33) + $X37*($L$28) + $Y37*($L$29) -> 3.1615956
K38: Y: The dependent variable (the variable you're trying to predict - in your case, "Tip") | T38: 1 | U38: 2 | V38: 2 | W38: 1 | X38: 3 | Y38: 16.31 | Z38: 2 | AA38: =$L$27+ $T38*($L$30) - $U38*($L$31) + $V38*($L$32) - $W38*($L$33) + $X38*($L$28) + $Y38*($L$29) -> 2.432507 | AB38: 2 | AF38: Male | AG38: No | AH38: Sat | AI38: Dinner | AJ38: 3 | AK38: 16.31 | AL38: 2 | AM38: =$L$27+ $T38*($L$30) - $U38*($L$31) + $V38*($L$32) - $W38*($L$33) + $X38*($L$28) + $Y38*($L$29) -> 2.432507
K39: b0: The intercept (the value of Y when all independent variables are 0) | T39: 2 | U39: 2 | V39: 2 | W39: 1 | X39: 3 | Y39: 16.93 | Z39: 3.07 | AA39: =$L$27+ $T39*($L$30) - $U39*($L$31) + $V39*($L$32) - $W39*($L$33) + $X39*($L$28) + $Y39*($L$29) -> 2.5200501 | AB39: 3.07 | AF39: Female | AG39: No | AH39: Sat | AI39: Dinner | AJ39: 3 | AK39: 16.93 | AL39: 3.07 | AM39: =$L$27+ $T39*($L$30) - $U39*($L$31) + $V39*($L$32) - $W39*($L$33) + $X39*($L$28) + $Y39*($L$29) -> 2.5200501
K40: b1, b2, ..., bn: The coefficients for each independent variable | T40: 1 | U40: 2 | V40: 2 | W40: 1 | X40: 3 | Y40: 18.69 | Z40: 2.31 | AA40: =$L$27+ $T40*($L$30) - $U40*($L$31) + $V40*($L$32) - $W40*($L$33) + $X40*($L$28) + $Y40*($L$29) -> 2.6564077 | AB40: 2.31 | AF40: Male | AG40: No | AH40: Sat | AI40: Dinner | AJ40: 3 | AK40: 18.69 | AL40: 2.31 | AM40: =$L$27+ $T40*($L$30) - $U40*($L$31) + $V40*($L$32) - $W40*($L$33) + $X40*($L$28) + $Y40*($L$29) -> 2.6564077
...

Sheet Home

Sheet Dashboard
G2: sex | H2: smoker | I2: day | J2: time | K2: size | L2: total_bill | M2: Tip | N2: Predicted Tip
G3: =OFFSET(Working!AF2,Working!$AV$6,0) -> Female | H3: =OFFSET(Working!AG2,Working!$AV$6,0) -> No | I3: =OFFSET(Working!AH2,Working!$AV$6,0) -> Sun | J3: =OFFSET(Working!AI2,Working!$AV$6,0) -> Dinner | K3: =OFFSET(Working!AJ2,Working!$AV$6,0) -> 2 | L3: =OFFSET(Working!AK2,Working!$AV$6,0) -> 16.99 | M3: =OFFSET(Working!AL2,Working!$AV$6,0) -> 1.01 | N3: =OFFSET(Working!AM2,Working!$AV$6,0) -> 2.3541617
G4: =OFFSET(Working!AF3,Working!$AV$6,0) -> Male | H4: =OFFSET(Working!AG3,Working!$AV$6,0) -> No | I4: =OFFSET(Working!AH3,Working!$AV$6,0) -> Sun | J4: =OFFSET(Working!AI3,Working!$AV$6,0) -> Dinner | K4: =OFFSET(Working!AJ3,Working!$AV$6,0) -> 3 | L4: =OFFSET(Working!AK3,Working!$AV$6,0) -> 10.34 | M4: =OFFSET(Working!AL3,Working!$AV$6,0) -> 1.66 | N4: =OFFSET(Working!AM3,Working!$AV$6,0) -> 1.8787073
G5: =OFFSET(Working!AF4,Working!$AV$6,0) -> Male | H5: =OFFSET(Working!AG4,Working!$AV$6,0) -> No | I5: =OFFSET(Working!AH4,Working!$AV$6,0) -> Sun | J5: =OFFSET(Working!AI4,Working!$AV$6,0) -> Dinner | K5: =OFFSET(Working!AJ4,Working!$AV$6,0) -> 3 | L5: =OFFSET(Working!AK4,Working!$AV$6,0) -> 21.01 | M5: =OFFSET(Working!AL4,Working!$AV$6,0) -> 3.5 | N5: =OFFSET(Working!AM4,Working!$AV$6,0) -> 2.8824978
G6: =OFFSET(Working!AF5,Working!$AV$6,0) -> Male | H6: =OFFSET(Working!AG5,Working!$AV$6,0) -> No | I6: =OFFSET(Working!AH5,Working!$AV$6,0) -> Sun | J6: =OFFSET(Working!AI5,Working!$AV$6,0) -> Dinner | K6: =OFFSET(Working!AJ5,Working!$AV$6,0) -> 2 | L6: =OFFSET(Working!AK5,Working!$AV$6,0) -> 23.68 | M6: =OFFSET(Working!AL5,Working!$AV$6,0) -> 3.31 | N6: =OFFSET(Working!AM5,Working!$AV$6,0) -> 2.9543138
G7: =OFFSET(Working!AF6,Working!$AV$6,0) -> Female | H7: =OFFSET(Working!AG6,Working!$AV$6,0) -> No | I7: =OFFSET(Working!AH6,Working!$AV$6,0) -> Sun | J7: =OFFSET(Working!AI6,Working!$AV$6,0) -> Dinner | K7: =OFFSET(Working!AJ6,Working!$AV$6,0) -> 4 | L7: =OFFSET(Working!AK6,Working!$AV$6,0) -> 24.59 | M7: =OFFSET(Working!AL6,Working!$AV$6,0) -> 3.61 | N7: =OFFSET(Working!AM6,Working!$AV$6,0) -> 3.4278725
G8: =OFFSET(Working!AF7,Working!$AV$6,0) -> Male | H8: =OFFSET(Working!AG7,Working!$AV$6,0) -> No | I8: =OFFSET(Working!AH7,Working!$AV$6,0) -> Sun | J8: =OFFSET(Working!AI7,Working!$AV$6,0) -> Dinner | K8: =OFFSET(Working!AJ7,Working!$AV$6,0) -> 4 | L8: =OFFSET(Working!AK7,Working!$AV$6,0) -> 25.29 | M8: =OFFSET(Working!AL7,Working!$AV$6,0) -> 4.71 | N8: =OFFSET(Working!AM7,Working!$AV$6,0) -> 3.4645096
G9: =OFFSET(Working!AF8,Working!$AV$6,0) -> Male | H9: =OFFSET(Working!AG8,Working!$AV$6,0) -> No | I9: =OFFSET(Working!AH8,Working!$AV$6,0) -> Sun | J9: =OFFSET(Working!AI8,Working!$AV$6,0) -> Dinner | K9: =OFFSET(Working!AJ8,Working!$AV$6,0) -> 2 | L9: =OFFSET(Working!AK8,Working!$AV$6,0) -> 8.77 | M9: =OFFSET(Working!AL8,Working!$AV$6,0) -> 2 | N9: =OFFSET(Working!AM8,Working!$AV$6,0) -> 1.5516413
G10: =OFFSET(Working!AF9,Working!$AV$6,0) -> Male | H10: =OFFSET(Working!AG9,Working!$AV$6,0) -> No | I10: =OFFSET(Working!AH9,Working!$AV$6,0) -> Sun | J10: =OFFSET(Working!AI9,Working!$AV$6,0) -> Dinner | K10: =OFFSET(Working!AJ9,Working!$AV$6,0) -> 4 | L10: =OFFSET(Working!AK9,Working!$AV$6,0) -> 26.88 | M10: =OFFSET(Working!AL9,Working!$AV$6,0) -> 3.12 | N10: =OFFSET(Working!AM9,Working!$AV$6,0) -> 3.6140904
M13: Tip | N13: size | O13: total_bill | P13: Sex2 | Q13: Smoker3 | R13: Day4 | S13: Dinner
L14: Tip | M14: 1
L15: size | M15: 0.48929878 | N15: 1
L16: total_bill | M16: 0.67573411 | N16: 0.59831513 | O16: 1
L17: Sex2 | M17: -0.088862061 | N17: -0.086194815 | O17: -0.14487734 | P17: 1
L18: Smoker3 | M18: -0.0059285395 | N18: 0.13317825 | O18: -0.085721257 | P18: 0.0028159517 | Q18: 1
L19: Day4 | M19: -0.13894712 | N19: -0.21175021 | O19: -0.17531197 | P19: 0.21537409 | Q19: -0.17081845 | R19: 1
L20: Dinner | M20: -0.12162906 | N20: -0.10341091 | O20: -0.18311761 | P20: 0.2052313 | Q20: 0.054921104 | R20: 0.67047036 | S20: 1
